I'm sorry, but an uncaught exception occurred.

While running game code:
  File "game/script.rpy", line 33, in script call
    call at_home
  File "game/at_home.rpy", line 134, in script call
    call travelling
  File "game/travelling.rpy", line 60, in script call
    call confrontation
  File "game/script.rpy", line 33, in script call
    call at_home
  File "game/at_home.rpy", line 134, in script call
    call travelling
  File "game/travelling.rpy", line 60, in script call
    call confrontation
ScriptError: could not find label 'confrontation'.

-- Full Traceback ------------------------------------------------------------

Full traceback:
  File "game/script.rpy", line 33, in script call
    call at_home
  File "game/at_home.rpy", line 134, in script call
    call travelling
  File "game/travelling.rpy", line 60, in script call
    call confrontation
  File "C:\Users\Geertje\Documents\Utrecht\Master Thesis\02_Second_phase\High-fi_prototype\renpy-8.0.3-sdk\renpy\ast.py", line 1705, in execute
    rv = renpy.game.context().call(label, return_site=self.next.name)
  File "game/script.rpy", line 33, in script call
    call at_home
  File "game/at_home.rpy", line 134, in script call
    call travelling
  File "game/travelling.rpy", line 60, in script call
    call confrontation
  File "C:\Users\Geertje\Documents\Utrecht\Master Thesis\02_Second_phase\High-fi_prototype\renpy-8.0.3-sdk\renpy\script.py", line 927, in lookup
    raise ScriptError("could not find label '%s'." % str(original))
ScriptError: could not find label 'confrontation'.

Windows-10-10.0.22621 AMD64
Ren'Py 8.0.3.22090809
Diverse Perspectives 1.0
Mon Apr 17 19:00:37 2023
